<?xml version="1.0" encoding="utf-8"?>
<!-- =================================================================================== -->
<!-- |    This document was autogenerated by xacro from gazebo_2f.xacro                | -->
<!-- |    EDITING THIS FILE BY HAND IS NOT RECOMMENDED                                 | -->
<!-- =================================================================================== -->
<robot name="abb_gripper">
  <!-- Conversion were obtained from http://www.e-paint.co.uk/Lab_values.asp
       unless otherwise stated. -->
  <!-- link list -->
  <link name="base_link">
    <inertial>
      <origin xyz="0.0 0.0 0.0"/>
      <mass value="120.00000"/>
      <inertia ixx="-4.98000" ixy="0.00000" ixz="2.70000" iyy="-5.95200" iyz="0.00000" izz="0.82800"/>
    </inertial>
    <visual>
      <geometry>
        <mesh filename="package://abb_irb4600_support/meshes/irb4600/visual/base_link.stl"/>
      </geometry>
      <material name="">
        <color rgba="0.7725490 0.7803922 0.7686275 1"/>
      </material>
    </visual>
    <collision>
      <geometry>
        <mesh filename="package://abb_irb4600_support/meshes/irb4600/collision/base_link.stl"/>
      </geometry>
    </collision>
  </link>
  <link name="link_1">
    <inertial>
      <origin xyz="0.18000 0.00000 0.50000"/>
      <mass value="120.00000"/>
      <inertia ixx="-4.98000" ixy="0.00000" ixz="2.70000" iyy="-5.95200" iyz="0.00000" izz="0.82800"/>
    </inertial>
    <visual>
      <geometry>
        <mesh filename="package://abb_irb4600_support/meshes/irb4600_40_255/visual/link_1.stl"/>
      </geometry>
      <material name="">
        <color rgba="0.7725490 0.7803922 0.7686275 1"/>
      </material>
    </visual>
    <collision>
      <geometry>
        <mesh filename="package://abb_irb4600_support/meshes/irb4600_40_255/collision/link_1.stl"/>
      </geometry>
    </collision>
  </link>
  <link name="link_2">
    <inertial>
      <origin xyz="0.94000 0.08000 -0.34000"/>
      <mass value="120.00000"/>
      <inertia ixx="-2.96000" ixy="2.25600" ixz="-9.58800" iyy="-18.72601" iyz="-0.81600" izz="-14.95000"/>
    </inertial>
    <visual>
      <geometry>
        <mesh filename="package://abb_irb4600_support/meshes/irb4600_40_255/visual/link_2.stl"/>
      </geometry>
      <material name="">
        <color rgba="0.7725490 0.7803922 0.7686275 1"/>
      </material>
    </visual>
    <collision>
      <geometry>
        <mesh filename="package://abb_irb4600_support/meshes/irb4600_40_255/collision/link_2.stl"/>
      </geometry>
    </collision>
  </link>
  <link name="link_3">
    <inertial>
      <origin xyz="0.07000 -0.26600 0.08800"/>
      <mass value="120.00000"/>
      <inertia ixx="1.34500" ixy="0.55860" ixz="0.18480" iyy="4.65068" iyz="-0.70224" izz="2.76032"/>
    </inertial>
    <visual>
      <geometry>
        <mesh filename="package://abb_irb4600_support/meshes/irb4600_40_255/visual/link_3.stl"/>
      </geometry>
      <material name="">
        <color rgba="0.7725490 0.7803922 0.7686275 1"/>
      </material>
    </visual>
    <collision>
      <geometry>
        <mesh filename="package://abb_irb4600_support/meshes/irb4600_40_255/collision/link_3.stl"/>
      </geometry>
    </collision>
  </link>
  <link name="link_4">
    <inertial>
      <origin xyz="0.00000 0.00000 1.00000"/>
      <mass value="40.00000"/>
      <inertia ixx="-8.00000" ixy="0.00000" ixz="0.00000" iyy="-8.00000" iyz="0.00000" izz="0.48200"/>
    </inertial>
    <visual>
      <geometry>
        <mesh filename="package://abb_irb4600_support/meshes/irb4600_40_255/visual/link_4.stl"/>
      </geometry>
      <material name="">
        <color rgba="0.7725490 0.7803922 0.7686275 1"/>
      </material>
    </visual>
    <collision>
      <geometry>
        <mesh filename="package://abb_irb4600_support/meshes/irb4600_40_255/collision/link_4.stl"/>
      </geometry>
    </collision>
  </link>
  <link name="link_5">
    <inertial>
      <origin xyz="0.14000 0.00000 0.00000"/>
      <mass value="10.00000"/>
      <inertia ixx="0.04000" ixy="0.00000" ixz="0.00000" iyy="-0.00900" iyz="0.00000" izz="-0.00400"/>
    </inertial>
    <visual>
      <geometry>
        <mesh filename="package://abb_irb4600_support/meshes/irb4600_40_255/visual/link_5.stl"/>
      </geometry>
      <material name="">
        <color rgba="0.7725490 0.7803922 0.7686275 1"/>
      </material>
    </visual>
    <collision>
      <geometry>
        <mesh filename="package://abb_irb4600_support/meshes/irb4600_40_255/collision/link_5.stl"/>
      </geometry>
    </collision>
  </link>
  <link name="link_6">
    <inertial>
      <origin xyz="0.08100 -0.09100 0.33200"/>
      <mass value="5.00000"/>
      <inertia ixx="-0.29652" ixy="-0.03686" ixz="0.09396" iyy="-0.28792" iyz="-0.10556" izz="-0.04621"/>
    </inertial>
    <visual>
      <geometry>
        <mesh filename="package://abb_irb4600_support/meshes/irb4600_40_255/visual/link_6.stl"/>
      </geometry>
      <material name="">
        <color rgba="0.1882353 0.1960784 0.2039216 1"/>
      </material>
    </visual>
    <collision>
      <geometry>
        <mesh filename="package://abb_irb4600_support/meshes/irb4600_40_255/collision/link_6.stl"/>
      </geometry>
    </collision>
  </link>
  <link name="tool0"/>
  <!-- end of link list -->
  <!-- joint list -->
  <joint name="joint_1" type="revolute">
    <parent link="base_link"/>
    <child link="link_1"/>
    <origin rpy="0 0 0 " xyz="0 0 0"/>
    <axis xyz="0 0 1"/>
    <!-- (-180 to 180) -->
    <limit effort="100000" lower="-3.14159265359" upper="3.14159265359" velocity="2.618"/>
    <dynamics damping="0.2" friction="0"/>
  </joint>
  <joint name="joint_2" type="revolute">
    <parent link="link_1"/>
    <child link="link_2"/>
    <origin rpy="0 0 0 " xyz="0.175 0 0.495"/>
    <axis xyz="0 1 0"/>
    <!-- (-90 to 150) -->
    <limit effort="100000" lower="-1.57079632679" upper="2.61799387799" velocity="2.618"/>
    <dynamics damping="0.2" friction="0"/>
  </joint>
  <joint name="joint_3" type="revolute">
    <parent link="link_2"/>
    <child link="link_3"/>
    <origin rpy="0 0 0 " xyz="0 0 1.095"/>
    <axis xyz="0 1 0"/>
    <!-- (-180 to 75) -->
    <limit effort="100000" lower="-3.14159265359" upper="1.308996939" velocity="2.618"/>
    <dynamics damping="0.2" friction="0"/>
  </joint>
  <joint name="joint_4" type="revolute">
    <parent link="link_3"/>
    <child link="link_4"/>
    <origin rpy="0 0 0 " xyz="0.331 0 0.175"/>
    <axis xyz="1 0 0"/>
    <!-- (-400 to 400) -->
    <limit effort="10000" lower="-6.98131700798" upper="6.98131700798" velocity="6.2832"/>
    <dynamics damping="0.2" friction="0"/>
  </joint>
  <joint name="joint_5" type="revolute">
    <parent link="link_4"/>
    <child link="link_5"/>
    <origin rpy="0 0 0 " xyz="0.939 0 0"/>
    <axis xyz="0 1 0"/>
    <!-- (-125 to 120) -->
    <limit effort="100000" lower="-2.18166" upper="2.18166156499" velocity="6.2832"/>
    <dynamics damping="0.2" friction="0"/>
  </joint>
  <joint name="joint_6" type="revolute">
    <parent link="link_5"/>
    <child link="link_6"/>
    <origin rpy="0 1.57079632679 0" xyz="0.135 0 0"/>
    <axis xyz="0 0 1"/>
    <!-- (-400 to 400) -->
    <limit effort="100000" lower="-6.98131700798" upper="6.98131700798" velocity="7.854"/>
    <dynamics damping="0.2" friction="0"/>
  </joint>
  <joint name="joint_6-tool0" type="fixed">
    <parent link="link_6"/>
    <child link="tool0"/>
    <origin rpy="0 0 0" xyz="0 0 0"/>
  </joint>
  <!-- end of joint list -->
  <!-- ROS base_link to ABB World Coordinates transform >
    <link name="${prefix}base" />
    <joint name="${prefix}base_link-base" type="fixed">
      <origin xyz="0 0 0" rpy="0 0 0"/>
      <parent link="${prefix}base_link"/>
      <child link="${prefix}base"/>
    </joint-->
  <!-- IRB4600 -->
  <transmission name="trans_left_inner_arb_joint">
    <type>transmission_interface/SimpleTransmission</type>
    <joint name="left_inner_arb_joint">
      <hardwareInterface>hardware_interface/PositionJointInterface</hardwareInterface>
    </joint>
    <actuator name="left_inner_arb_joint_motor">
      <hardwareInterface>hardware_interface/PositionJointInterface</hardwareInterface>
      <mechanicalReduction>1</mechanicalReduction>
    </actuator>
  </transmission>
  <transmission name="trans_left_inner_finger_joint">
    <type>transmission_interface/SimpleTransmission</type>
    <joint name="left_inner_finger_joint">
      <hardwareInterface>hardware_interface/PositionJointInterface</hardwareInterface>
    </joint>
    <actuator name="left_inner_finger_joint_motor">
      <hardwareInterface>hardware_interface/PositionJointInterface</hardwareInterface>
      <mechanicalReduction>1</mechanicalReduction>
    </actuator>
  </transmission>
  <transmission name="trans_right_outer_arb_joint">
    <type>transmission_interface/SimpleTransmission</type>
    <joint name="right_outer_arb_joint">
      <hardwareInterface>hardware_interface/PositionJointInterface</hardwareInterface>
    </joint>
    <actuator name="right_outer_arb_joint_motor">
      <hardwareInterface>hardware_interface/PositionJointInterface</hardwareInterface>
      <mechanicalReduction>1</mechanicalReduction>
    </actuator>
  </transmission>
  <transmission name="trans_right_inner_arb_joint">
    <type>transmission_interface/SimpleTransmission</type>
    <joint name="right_inner_arb_joint">
      <hardwareInterface>hardware_interface/PositionJointInterface</hardwareInterface>
    </joint>
    <actuator name="right_inner_arb_joint_motor">
      <hardwareInterface>hardware_interface/PositionJointInterface</hardwareInterface>
      <mechanicalReduction>1</mechanicalReduction>
    </actuator>
  </transmission>
  <transmission name="trans_right_inner_finger_joint">
    <type>transmission_interface/SimpleTransmission</type>
    <joint name="right_inner_finger_joint">
      <hardwareInterface>hardware_interface/PositionJointInterface</hardwareInterface>
    </joint>
    <actuator name="right_inner_finger_joint_motor">
      <hardwareInterface>hardware_interface/PositionJointInterface</hardwareInterface>
      <mechanicalReduction>1</mechanicalReduction>
    </actuator>
  </transmission>
  <gazebo>
    <!-- loading plugin: mimic joints works in gazebo now -->
    <plugin filename="libroboticsgroup_upatras_gazebo_mimic_joint_plugin.so" name="mimic_robotiq_85_1">
      <joint>finger_joint</joint>
      <mimicJoint>right_outer_arb_joint</mimicJoint>
      <multiplier>1.0</multiplier>
      <!--<offset>0.0</offset-->
    </plugin>
    <plugin filename="libroboticsgroup_upatras_gazebo_mimic_joint_plugin.so" name="mimic_robotiq_85_5">
      <joint>finger_joint</joint>
      <mimicJoint>left_inner_finger_joint</mimicJoint>
      <multiplier>-1.0</multiplier>
      <!--offset>0.0</offset-->
    </plugin>
    <plugin filename="libroboticsgroup_upatras_gazebo_mimic_joint_plugin.so" name="mimic_robotiq_85_4">
      <joint>finger_joint</joint>
      <mimicJoint>right_inner_finger_joint</mimicJoint>
      <multiplier>-1.0</multiplier>
      <!--offset>0.0</offset-->
    </plugin>
    <plugin filename="libroboticsgroup_upatras_gazebo_mimic_joint_plugin.so" name="mimic_robotiq_85_2">
      <joint>finger_joint</joint>
      <mimicJoint>left_inner_arb_joint</mimicJoint>
      <multiplier>1.0</multiplier>
      <!--<offset>0.0</offset-->
    </plugin>
    <plugin filename="libroboticsgroup_upatras_gazebo_mimic_joint_plugin.so" name="mimic_robotiq_85_3">
      <joint>finger_joint</joint>
      <mimicJoint>right_inner_arb_joint</mimicJoint>
      <multiplier>1.0</multiplier>
      <!--<offset>0.0</offset-->
    </plugin>
  </gazebo>
  <!-- Plugin -->
  <gazebo>
    <plugin filename="libgazebo_grasp_fix.so" name="gazebo_grasp_fix">
      <arm>
        <arm_name>abb_irb4600_40_255</arm_name>
        <palm_link>link_6</palm_link>
        <gripper_link>left_outer_arb_joint</gripper_link>
        <gripper_link>right_outer_arb_joint</gripper_link>
        <gripper_link>left_inner_finger_joint</gripper_link>
        <gripper_link>right_inner_finger_joint</gripper_link>
      </arm>
      <forces_angle_tolerance>90</forces_angle_tolerance>
      <update_rate>4</update_rate>
      <grip_count_threshold>4</grip_count_threshold>
      <max_grip_count>8</max_grip_count>
      <release_tolerance>0.005</release_tolerance>
      <disable_collisions_on_attach>false</disable_collisions_on_attach>
      <contact_topic>__default_topic__</contact_topic>
    </plugin>
  </gazebo>
</robot>

